<?xml version="1.0" ?>
<robot name="edu_amr" xmlns:xacro="http://www.ros.org/wiki/xacro">

<xacro:include filename="$(find edu_amr_description)/urdf/materials.xacro" />
<xacro:include filename="$(find edu_amr_description)/urdf/edu_amr.trans" />
<xacro:include filename="$(find edu_amr_description)/urdf/edu_amr.gazebo" />

<link name="base_link">
  <inertial>
    <origin xyz="-0.02222141938082127 -0.00036192202124805104 0.09520868144869932" rpy="0 0 0"/>
    <mass value="2.6485187031603292"/>
    <inertia ixx="0.013976" iyy="0.015848" izz="0.008361" ixy="2e-06" iyz="-3.5e-05" ixz="-0.000507"/>
  </inertial>
  <visual>
    <origin xyz="0 0 0" rpy="0 0 0"/>
    <geometry>
      <mesh filename="package://edu_amr_description/meshes/base_link.stl" scale="0.001 0.001 0.001"/>
    </geometry>
    <material name="silver"/>
  </visual>
  <collision>
    <origin xyz="0 0 0" rpy="0 0 0"/>
    <geometry>
      <mesh filename="package://edu_amr_description/meshes/base_link.stl" scale="0.001 0.001 0.001"/>
    </geometry>
  </collision>
</link>

<link name="left_wheel_1">
  <inertial>
    <origin xyz="2.7938483943001913e-08 -0.008809196335037156 -6.264050599058546e-08" rpy="0 0 0"/>
    <mass value="0.27294370957502523"/>
    <inertia ixx="0.000119" iyy="0.0002" izz="0.000119" ixy="0.0" iyz="-0.0" ixz="0.0"/>
  </inertial>
  <visual>
    <origin xyz="0.065 -0.095 -0.0325" rpy="0 0 0"/>
    <geometry>
      <mesh filename="package://edu_amr_description/meshes/left_wheel_1.stl" scale="0.001 0.001 0.001"/>
    </geometry>
    <material name="black"/>
  </visual>
  <collision>
    <origin xyz="0.065 -0.095 -0.0325" rpy="0 0 0"/>
    <geometry>
      <mesh filename="package://edu_amr_description/meshes/left_wheel_1.stl" scale="0.001 0.001 0.001"/>
    </geometry>
  </collision>
</link>

<link name="right_wheel_1">
  <inertial>
    <origin xyz="-8.051599123537478e-09 0.00880921502843407 -6.264050686488609e-08" rpy="0 0 0"/>
    <mass value="0.2729437095750096"/>
    <inertia ixx="0.000119" iyy="0.0002" izz="0.000119" ixy="0.0" iyz="0.0" ixz="-0.0"/>
  </inertial>
  <visual>
    <origin xyz="0.065 0.095 -0.0325" rpy="0 0 0"/>
    <geometry>
      <mesh filename="package://edu_amr_description/meshes/right_wheel_1.stl" scale="0.001 0.001 0.001"/>
    </geometry>
    <material name="black"/>
  </visual>
  <collision>
    <origin xyz="0.065 0.095 -0.0325" rpy="0 0 0"/>
    <geometry>
      <mesh filename="package://edu_amr_description/meshes/right_wheel_1.stl" scale="0.001 0.001 0.001"/>
    </geometry>
  </collision>
</link>

<link name="imu_1">
  <inertial>
    <origin xyz="1.2277505791965376e-05 9.132307373265966e-05 0.000861898562579344" rpy="0 0 0"/>
    <mass value="0.004997129426507195"/>
    <inertia ixx="0.0" iyy="0.0" izz="0.0" ixy="0.0" iyz="-0.0" ixz="-0.0"/>
  </inertial>
  <visual>
    <origin xyz="0.019801 0.026021 -0.062522" rpy="0 0 0"/>
    <geometry>
      <mesh filename="package://edu_amr_description/meshes/imu_1.stl" scale="0.001 0.001 0.001"/>
    </geometry>
    <material name="blue"/>
  </visual>
  <collision>
    <origin xyz="0.019801 0.026021 -0.062522" rpy="0 0 0"/>
    <geometry>
      <mesh filename="package://edu_amr_description/meshes/imu_1.stl" scale="0.001 0.001 0.001"/>
    </geometry>
  </collision>
</link>

<link name="camera_1">
  <inertial>
    <origin xyz="0.001391276525945298 -6.565133329183315e-05 -0.0003892293542707148" rpy="0 0 0"/>
    <mass value="0.0067428696514978854"/>
    <inertia ixx="0.0" iyy="0.0" izz="0.0" ixy="0.0" iyz="0.0" ixz="0.0"/>
  </inertial>
  <visual>
    <origin xyz="-0.044 -0.0 -0.1655" rpy="0 0 0"/>
    <geometry>
      <mesh filename="package://edu_amr_description/meshes/camera_1.stl" scale="0.001 0.001 0.001"/>
    </geometry>
    <material name="green"/>
  </visual>
  <collision>
    <origin xyz="-0.044 -0.0 -0.1655" rpy="0 0 0"/>
    <geometry>
      <mesh filename="package://edu_amr_description/meshes/camera_1.stl" scale="0.001 0.001 0.001"/>
    </geometry>
  </collision>
</link>

<link name="lidar_1">
  <inertial>
    <origin xyz="-4.241334066457103e-07 -4.671755761875305e-18 0.008999999999999952" rpy="0 0 0"/>
    <mass value="0.47757295201389544"/>
    <inertia ixx="0.000141" iyy="0.000141" izz="0.000257" ixy="-0.0" iyz="-0.0" ixz="0.0"/>
  </inertial>
  <visual>
    <origin xyz="0.036095 0.0 -0.194" rpy="0 0 0"/>
    <geometry>
      <mesh filename="package://edu_amr_description/meshes/lidar_1.stl" scale="0.001 0.001 0.001"/>
    </geometry>
    <material name="black"/>
  </visual>
  <collision>
    <origin xyz="0.036095 0.0 -0.194" rpy="0 0 0"/>
    <geometry>
      <mesh filename="package://edu_amr_description/meshes/lidar_1.stl" scale="0.001 0.001 0.001"/>
    </geometry>
  </collision>
</link>

<joint name="left_wheel_joint" type="continuous">
  <origin xyz="-0.065 0.095 0.0325" rpy="0 0 0"/>
  <parent link="base_link"/>
  <child link="left_wheel_1"/>
  <axis xyz="0.0 1.0 0.0"/>
</joint>

<joint name="right_wheel_joint" type="continuous">
  <origin xyz="-0.065 -0.095 0.0325" rpy="0 0 0"/>
  <parent link="base_link"/>
  <child link="right_wheel_1"/>
  <axis xyz="0.0 1.0 0.0"/>
</joint>

<joint name="imu_joint" type="fixed">
  <origin xyz="-0.019801 -0.026021 0.062522" rpy="0 0 0"/>
  <parent link="base_link"/>
  <child link="imu_1"/>
</joint>

<joint name="camera_joint" type="fixed">
  <origin xyz="0.044 0.0 0.1655" rpy="0 0 0"/>
  <parent link="base_link"/>
  <child link="camera_1"/>
</joint>

<joint name="lidar_joint" type="fixed">
  <origin xyz="-0.036095 0.0 0.194" rpy="0 0 0"/>
  <parent link="base_link"/>
  <child link="lidar_1"/>
</joint>

</robot>
